Workbook
Name ListA: #REF!
Name ListCheck: [1]リスト!#REF!
Name ListCheck2: [2]リスト!$M$3:$M$7
Name ListHantei: #REF!
Name ListRiyu: #REF!
Name List工法_RC: [2]リスト!$J$3:$J$23
Name List工法_塩害: [1]リスト!$B$3:$B$27
Name List工法_塗装: [1]リスト!$D$3:$D$9
Name List事項: [2]リスト!$A$3:$A$5
Name List事項222: #REF!
Name List実施チェック: [1]リスト!#REF!
Name List選択: [1]リスト!#REF!
Name List補修工法: [1]リスト!$A$3:$A$60
Name List補修実施箇所: [2]リスト!$B$3:$B$7
Name List補修実施箇所2: [2]リスト!$C$3:$C$6
Name List理由: [1]リスト!#REF!
Name List理由2: [1]リスト!#REF!
Name Riuu: #REF!
Name あああ: #REF!
Name ああああああああああ: #REF!
Name ぃｓｔ: #REF!

Sheet 橋梁諸元
AH1: 様式1
A2: 橋梁諸元と総合点検結果
A3: 橋梁名 | D3: 吉田橋 | N3: 路線名 | Q3: 吉田下田線 | X3: 施設ID
A4: 所在地 | D4: 自 | E4: 仙北市西木町桧木内 | N4: 起点 座標 | Q4: 緯度 | R4: 39°44′54.20″ | X4: 管理者 | Z4: 秋田県仙北市
D5: 至 | E5: 仙北市西木町桧木内 | Q5: 経度 | R5: 140°36′00.00″ | Z5: 建設部建設課
A7: 架設年度 | F7: 1984年 | L7: 活荷重・等級 | Q7: 不明 | X7: 適用示方書 | AB7: S55 道路橋示方書
A8: 橋長 | F8: 34.0m | L8: 総径間数 | Q8: 1径間 | X8: 点検日 | AB8: 2025.9.24
A9: 上部構造形式 | F9: PC･ポステンT桁 | L9: 下部構造形式 | Q9: 半重力式橋台 | X9: 基礎形式 | AB9: 直接基礎
A10: 交通条件 | E10: 調査年 | H10: 未実施 | R10: 大型車混入率 | W10: -
E11: 交通量 | H11: -(昼間12時間) | R11: 荷重制限 | W11: -
A12: 幅員 | B12: 全幅員 | F12: 8.5m | I12: 地覆幅 | L12: 歩道幅 | O12: 車道幅・車線 | T12: 車道幅・車線 | Y12: 歩道幅 | AB12: 地覆幅 | AE12: 中央帯
B13: 有効幅員 | F13: 7.3m | I13: 0.6m | L13: 0.0m | O13: 3.65m | S13: 1 | T13: 3.65m | X13: 1 | Y13: 0.0m | AB13: 0.6m | AE13: 0.0m
A14: 海岸からの距離 | G14: 20km以上 | L14: 緊急輸送路の指定 | S14: 無し | W14: 迂回路の有無 | AE14: 有
A15: 路下条件 | G15: 河川
A17: 全体図
A25: 径間別一般図

Sheet 橋梁諸元2
A1: 橋梁諸元等データ
A2: 県名 | C2: 秋田県 | H2: 地方公共団体名 | N2: 仙北市 | T2: 事務所名 | X2: 建設部建設課
A4: 橋梁管理番号 | F4: 8-1 | N4: 橋梁番号 | R4: 8-1
A5: 橋梁名称 | E5: 吉田橋 | O5: カナ | Q5: ヨシダハシ
A6: 路線コード | E6: 8 | I6: 路線名 | L6: 吉田下田線 | T6: カナ | V6: ヨシダシモダセン
A7: 架設年月 | E7: 1984 | H7: 年 | I7: 8 | K7: 月
A8: 道路種別 | E8: 市町村道 1級 | N8: 現旧区分 | R8: 現道
A10: 橋梁種別 | E10: 橋 | I10: 分割番号 | M10: 0 | O10: 分割区分 | S10: 全線一体
A11: 径間数 | D11: 1 | H11: 橋長 | J11: 34 | O11: m | P11: 道路部幅員 | T11: 7.3 | W11: m
A13: 所在地 | D13: 仙北市西木町桧木内 | R13: 距離標 | Z13: km
A14: 緯度 | C14: 39°44′54.20″ | I14: 経度 | K14: 140°36′00.00″
A16: 塩害地域 | E16: 該当せず | H16: 海岸からの距離 | N16: 20km以上 | Q16: ㎞ | R16: 塩害地域区分 | W16: -
A18: 大型車交通量24時間 | M18: 台 | N18: センサス年度 | V18: 年
A19: 架橋条件 | E19: 河川・開水路・湖沼 | O19: 緊急輸送路の指定 | U19: 無し

Sheet 上部工諸元
A1: 上部工諸元
A2: 橋梁管理番号 | F2: 8-1 | O2: 橋梁名 | S2: 吉田橋
A4: 径間番号 | E4: 1
A5: 材料区分 | E5: PC橋 | O5: 支間長 | R5: 33 | U5: m | X5: 桁高 | AE5: m
A6: 桁本数 | E6: 4
A7: 構造形式 | E7: PC･ポステンT桁
C8: 床版材料 | K8: コンクリート系 | X8: 床版厚 | AE8: cm
C9: 床版種類使用形式 | X9: 床版防水
C10: プライマー下塗り塗料
C11: 中塗り塗料
C12: 上塗り塗料
C13: 起点側躯体番号 | K13: A1 | O13: 起点側支承種類 | U13: ゴム支承
C14: 終点側躯体番号 | K14: A2 | O14: 終点側支承種類 | U14: ゴム支承
C15: 起点側伸縮装置種類 | K15: 不明
C16: 終点側伸縮装置種類 | K16: 不明

Sheet 下部工諸元
A1: 橋梁管理番号 | C1: 橋梁名
A2: 8-1 | C2: 吉田橋
A4: 躯体番号 | B4: 材料区分 | C4: 下部工 構造高 (m) | D4: 下部工構造形式 | E4: プライマー 下塗り塗料 | F4: 中塗り塗料 | G4: 上塗り塗料
A5: A1 | B5: コンクリート系 | D5: 重力式橋台
A6: A2 | B6: コンクリート系 | D6: 重力式橋台

Sheet 補修履歴
A1: 橋梁管理番号 | C1: 橋梁名
A2: 8-1 | C2: 吉田橋
A4: 径間 番号 | B4: 補修 改良年 | C4: 部材種別名称 | D4: 部材 番号 | E4: 補修・補強工法名称 | F4: 備考

Sheet 現況写真台帳
A1: 現況写真台帳
A2: 橋梁管理番号 | B2: 8-1 | C2: 橋梁名 | D2: =橋梁諸元!$D$3 -> 吉田橋 | E2: 路線名 | F2: =橋梁諸元!$Q$3 -> 吉田下田線
F3: 写真番号 | G3: 1
F4: 径間番号 | G4: 1
F5: 写真説明 | G5: 起点全景
F6: メ モ
F10: 写真番号 | G10: 2
F11: 径間番号 | G11: 1
F12: 写真説明 | G12: 終点全景
F13: メ モ
F17: 写真番号 | G17: 3
F18: 径間番号 | G18: 1
F19: 写真説明 | G19: 右側面
F20: メ モ
A24: 現況写真台帳
A25: 橋梁管理番号 | B25: 8-1 | C25: 橋梁名 | D25: =橋梁諸元!$D$3 -> 吉田橋 | E25: 路線名 | F25: =橋梁諸元!$Q$3 -> 吉田下田線
F26: 写真番号 | G26: 4
F27: 径間番号 | G27: 1
F28: 写真説明 | G28: 左側面
F29: メ モ
F33: 写真番号 | G33: 5
F34: 径間番号 | G34: 1
F35: 写真説明 | G35: 伸縮装置A1
F36: メ モ
F40: 写真番号 | G40: 6
F41: 径間番号 | G41: 1
F42: 写真説明 | G42: 伸縮装置A2
F43: メ モ
A47: 現況写真台帳
A48: 橋梁管理番号 | B48: 8-1 | C48: 橋梁名 | D48: =橋梁諸元!$D$3 -> 吉田橋 | E48: 路線名 | F48: =橋梁諸元!$Q$3 -> 吉田下田線
F49: 写真番号 | G49: 7
F50: 径間番号 | G50: 1
F51: 写真説明 | G51: 地覆（右）
F52: メ モ
F56: 写真番号 | G56: 8
F57: 径間番号 | G57: 1
F58: 写真説明 | G58: 地覆（左）
F59: メ モ
F63: 写真番号 | G63: 9
F64: 径間番号 | G64: 1
...

Sheet 第1径間
U1: 様式2
A2: 損傷程度の評価結果 | C2: 径間番号 | F2: 1
A3: 損傷の 種類等 主要な部材・ 部材番号 | C3: 鋼部材の損傷 | I3: コンクリート部材の損傷 | O3: 共通・その他 | U3: 備考
C4: 腐食 | D4: 亀裂 | E4: ボルトの脱落 | F4: 破断 | G4: 防食機能の劣化 | H4: (分類番号) | I4: ひびわれ・漏水・遊離石灰 | J4: (パターン番号) | K4: 鉄筋露出 | L4: 抜け落ち | M4: 床版ひびわれ | N4: PC定着部の異常 | O4: 路面の凹凸 | P4: 支承の機能障害 | Q4: 補修・補強材の損傷 | R4: (分類番号) | S4: 沈下・移動・傾斜 | T4: 洗堀
A5: 主桁 | B5: 1 | I5: a | J5: ― | K5: a | N5: a
B6: 2 | I6: a | J6: ― | K6: a | N6: a
B7: 3 | I7: a | J7: ― | K7: a | N7: a
B8: 4 | I8: a | J8: ― | K8: a | N8: a | U8: 鉄筋露出
B9: 5 | I9: d | J9: ㉒ | K9: a | N9: a
B10: 6 | I10: a | J10: ― | K10: a | N10: a
A11: 横桁 | B11: 1 | I11: d | J11: ㉔ | K11: a | N11: a
B12: 2 | I12: a | J12: ― | K12: a | N12: e | U12: うき
B13: 3 | I13: a | J13: ― | K13: a | N13: a
A14: 床版 | B14: 1 | K14: a | L14: a | M14: a | N14: a | U14: うき
B15: 2 | K15: a | L15: a | M15: a | N15: a
B16: 3 | K16: a | L16: a | M16: a | N16: a | U16: 鉄筋露出
B17: 4 | K17: a | L17: a | M17: a | N17: a
B18: 5 | K18: a | L18: a | M18: a | N18: a
A19: 下部工 | B19: 1 | I19: c | J19: ① | K19: a | N19: a | S19: a | U19: 植生
B20: 2 | I20: c | J20: ① | K20: a | N20: a | S20: a | U20: 漏水跡、土砂詰り
A21: 支承 | B21: 101 | P21: a
B22: 102 | P22: a
B23: 103 | P23: a
B24: 104 | P24: a
B25: 105 | P25: a
B26: 106 | P26: a
B27: 201 | P27: a
B28: 202 | P28: a
B29: 203 | P29: a
B30: 204 | P30: a
A31: 路面 | B31: 1 | O31: e | U31: 土砂堆積、ひびわれ
A32: その他 | B32: 伸縮装置：土砂詰り、ゴム劣化、欠損 地覆：剥離、欠損、鉄筋露出 防護柵：防食機能の劣化、変形、ボルトの変形 排水管：腐食、欠損 添架物：支持金具の腐食、変形

Sheet 部材番号図
A1: 部材番号図
A2: 橋梁管理番号 | B2: =現況写真台帳!$B$2 -> 8-1 | C2: 橋梁名 | D2: =橋梁諸元!$D$3 -> 吉田橋 | E2: 路線名 | F2: =橋梁諸元!$Q$3 -> 吉田下田線
F3: 部材番号図No | G3: 1
F4: 径間番号 | G4: 1
F10: 部材番号図No | G10: 2
F11: 径間番号 | G11: 1
F17: 部材番号図No | G17: 3
F18: 径間番号 | G18: 1

Sheet 損傷図
A1: 損傷図
A2: 橋梁管理番号 | B2: =現況写真台帳!$B$2 -> 8-1 | C2: 橋梁名 | D2: =橋梁諸元!$D$3 -> 吉田橋 | E2: 路線名 | F2: =橋梁諸元!$Q$3 -> 吉田下田線
F3: 損傷図No | G3: 1
F4: 径間番号 | G4: 1
F10: 損傷図No | G10: 2
F11: 径間番号 | G11: 1
F17: 損傷図No | G17: 3
F18: 径間番号 | G18: 1
F24: 損傷図No | G24: 4
F25: 径間番号 | G25: 1
F31: 損傷図No
F32: 径間番号
F38: 損傷図No
F39: 径間番号

Sheet 損傷写真台帳
B1: 損傷写真台帳
B2: 橋梁管理番号 | C2: =現況写真台帳!$B$2 -> 8-1 | D2: 橋梁名 | E2: =橋梁諸元!$D$3 -> 吉田橋 | F2: 路線名 | G2: =橋梁諸元!$Q$3 -> 吉田下田線
G3: 写真番号 | H3: 1
G4: 径間番号 | H4: 1
G5: 部材名称 | H5: 路面
G6: 部材番号 | H6: 01
G7: 損傷発生位置 | H7: 起点側下流
G8: メ モ
G9: 路面の凹凸が見られる。 路面の凹凸-e
G10: 写真番号 | H10: 2
G11: 径間番号 | H11: 1
G12: 部材名称 | H12: 路面
G13: 部材番号 | H13: 01
G14: 損傷発生位置 | H14: 起点側下流
G15: メ モ
G16: 写真番号1 (D=25mm)
G17: 写真番号 | H17: 3
G18: 径間番号 | H18: 1
G19: 部材名称 | H19: 路面
G20: 部材番号 | H20: 01
G21: 損傷発生位置 | H21: 起点側上流
G22: メ モ
G23: 土砂詰りが見られる。
G24: 写真番号 | H24: 4
G25: 径間番号 | H25: 1
G26: 部材名称 | H26: 路面
G27: 部材番号 | H27: 01
G28: 損傷発生位置 | H28: 中央部下流
G29: メ モ
G30: 舗装の異常(ひびわれ)が見られる。 (10.0mm)
G31: 写真番号 | H31: 5
G32: 径間番号 | H32: 1
G33: 部材名称 | H33: 路面
G34: 部材番号 | H34: 01
G35: 損傷発生位置 | H35: 終点側下流
G36: メ モ
G37: 路面の凹凸が見られる。 路面の凹凸-e
G38: 写真番号 | H38: 6
G39: 径間番号 | H39: 1
G40: 部材名称 | H40: 路面
...
